#VRML_SIM R2019a utf8
WorldInfo {
}
Viewpoint {
  orientation -0.7941638723008185 0.5798839471775796 0.1817645502784282 0.7518437617070588
  position 1.2676920295660519 2.1188367212830386 1.544755959803288
}
TexturedBackground {
}
TexturedBackgroundLight {
}
Floor {
}
Solid {
  translation 0 0.5 0
  children [
    Shape {
      appearance PBRAppearance {
        baseColor 0 0 0
      }
      geometry DEF DEF_CYL_1 Cylinder {
        height 1
        radius 0.15
      }
    }
    HingeJoint {
      jointParameters HingeJointParameters {
        axis 0 1 0
        anchor 0 0.5 0
        staticFriction 0.01
      }
      endPoint Solid {
        translation 0.25 0.51 0
        children [
          DEF G_RED_TABLE Shape {
            appearance PBRAppearance {
              baseColor 0.9372549019607843 0.1607843137254902 0.1607843137254902
            }
            geometry Box {
              size 0.5 0.01 0.1
            }
          }
          HingeJoint {
            jointParameters HingeJointParameters {
              axis 0 0 1
              anchor 0.25 0 0
              staticFriction 0.01
            }
            endPoint Solid {
              translation 0.3 0 0
              rotation 0 0 1 0
              children [
                DEF G_GREEN_TABLE Shape {
                  appearance PBRAppearance {
                    baseColor 0.45098039215686275 0.8235294117647058 0.08627450980392157
                  }
                  geometry Box {
                    size 0.1 0.01 0.1
                  }
                }
                HingeJoint {
                  jointParameters HingeJointParameters {
                    anchor 0.05 0 0
                    staticFriction 0.01
                  }
                  endPoint Solid {
                    translation 0.125 0 0
                    rotation 1 0 0 0
                    children [
                      DEF G_BLUE_TABLE Shape {
                        appearance PBRAppearance {
                          baseColor 0.12549019607843137 0.2901960784313726 0.5294117647058824
                        }
                        geometry Box {
                          size 0.15 0.01 0.1
                        }
                      }
                    ]
                    boundingObject USE G_BLUE_TABLE
                    physics Physics {
                    }
                  }
                }
              ]
              boundingObject USE G_GREEN_TABLE
              physics Physics {
              }
            }
          }
        ]
        boundingObject USE G_RED_TABLE
        physics Physics {
        }
      }
    }
  ]
  name "solid(1)"
}
